export const catchAsyncError = (theFunc)=>{
    return (req, res, next)=>{
        Promise.resolve(theFunc(req, res, next)).catch(next);
    };

};